Workbook
Name AttritionReasonCategories: tblAttritionReasonCategory[Attrition Reason Category]
Name AttritionReasons: tblAttritionReasons[Attrition Reasons]
Name AttritionTypes: tblAttritionTypes[Attrition Types]
Name CandidateSources: tblCandidateSources[Candidate Sources]
Name CostTypes: tblCostType[Cost Type]
Name Departments: tblDepartments[Departments]
Name EmployeeStatuses: tblEmployeeStatuses[Employee Statuses]
Name EmploymentTypes: tblEmploymentTypes[Employment Types]
Name HiringPriorities: tblHiringPriorities[Hiring Priorities]
Name JobFamilies: tblJobFamilies[Job Families]
Name OfferStatuses: tblOfferStatuses[Offer Statuses]
Name RecruitmentStages: tblRecruitmentStages[Recruitment Stages]
Name RequisitionStatuses: tblRequisitionStatuses[Requisition Statuses]
Name RiskCategories: tblRiskCategories[Risk Categories]
Name SLAStatuses: tblSLAStatuses[SLA Statuses]

Sheet 00_ReadMe
A1: HR Workforce Analytics Tracker
A2: Formula-driven, audit-ready portfolio workbook using synthetic data only.
A4: Project | B4: HR Workforce Analytics Tracker | H4: SOP Step | J4: Process Guidance | N4: Owner
A5: Company Scenario | B5: Northstar Financing Corporation | H5: 1. Update source tables | J5: Add or import new employee, requisition, recruitment, onboarding, attrition, cost, headcount, and productivity records. | N5: HR Staff
A6: Purpose | B6: Centralized HR operations and workforce analytics system for a fictional mid-sized financing company. | H6: 2. Validate data | J6: Open 18_QA_Checks and resolve any Fail/Review items before reporting. | N6: HR Staff / HR Manager
A7: Architecture | B7: Synthetic Source Tables → Calculation Layer → Analysis Summary → Dashboards → Power BI / SQL documentation. | H7: 3. Review calculation layer | J7: Confirm reporting start/end dates and review formula-driven helper outputs. | N7: HR Manager
A8: Important Rule | B8: Source/sample records and documentation are intentionally static. KPI cards, summaries, QA checks, risk scores, and chart sources are formula-driven. | H8: 4. Review dashboards | J8: Use dashboard views for HR operations, managerial review, and executive reporting. | N8: HR Manager / Executives
A9: Data Privacy | B9: Synthetic data only; no real employee or company data used. | H9: 5. Refresh BI model | J9: If using Power BI, refresh imported Excel tables and validate DAX measures. | N9: BI Analyst
A10: Primary Users | B10: HR staff, HR managers, department heads, finance/management, executives.
A11: How to Use | B11: Update source tables, review QA checks, refresh formulas/charts, and use dashboards for decisions.
A14: Sheet | B14: Type | C14: Purpose | D14: Update Frequency | F14: RACI Activity | G14: HR Staff | H14: HR Manager | I14: Department Head | J14: Finance | K14: Executive
A15: 00_ReadMe | B15: Documentation/Output | C15: See sheet title and data dictionary for details. | D15: As needed | F15: Maintain employee data | G15: R | H15: A | I15: C | J15: I | K15: I
A16: 01_Data_Dictionary | B16: Documentation/Output | C16: See sheet title and data dictionary for details. | D16: As needed | F16: Approve manpower request | G16: C | H16: A | I16: R | J16: C | K16: I
A17: 02_Lookup_Lists | B17: Documentation/Output | C17: See sheet title and data dictionary for details. | D17: As needed | F17: Track candidates | G17: R | H17: A | I17: I | J17: I | K17: I
A18: 03_Employee_Master | B18: Source | C18: See sheet title and data dictionary for details. | D18: As needed | F18: Validate hiring costs | G18: C | H18: I | I18: I | J18: A/R | K18: I
A19: 04_Department_Position_Master | B19: Source | C19: See sheet title and data dictionary for details. | D19: As needed | F19: Review dashboards | G19: I | H19: R | I19: R | J19: C | K19: A
A20: 05_Requisitions_MRF | B20: Source | C20: See sheet title and data dictionary for details. | D20: As needed | F20: Act on attrition risk | G20: C | H20: R | I20: A/R | J20: I | K20: I
A21: 06_Recruitment_Pipeline | B21: Source | C21: See sheet title and data dictionary for details. | D21: As needed
A22: 07_Hiring_Costs | B22: Source | C22: See sheet title and data dictionary for details. | D22: As needed | F22: This workbook uses synthetic data only and is intended as a portfolio project to demonstrate HR analytics, workforce planning, Excel systems design, SQL-readiness, Power BI-readiness, and dashboard reporting. | J22: Legends: R = Responsible A = Accountable C = Consulted I = Informed
A23: 08_Onboarding_Tracker | B23: Source | C23: See sheet title and data dictionary for details. | D23: As needed
A24: 09_Attrition_Tracker | B24: Source | C24: See sheet title and data dictionary for details. | D24: As needed
A25: 10_Productivity_Inputs | B25: Source | C25: See sheet title and data dictionary for details. | D25: As needed
A26: 11_Headcount_Snapshot | B26: Source | C26: See sheet title and data dictionary for details. | D26: As needed
A27: 12_Calculation_Layer | B27: Documentation/Output | C27: See sheet title and data dictionary for details. | D27: As needed
A28: 13_Analysis_Summary | B28: Documentation/Output | C28: See sheet title and data dictionary for details. | D28: As needed
A29: 14_Dashboard_HR_Ops | B29: Dashboard | C29: See sheet title and data dictionary for details. | D29: Auto-updates from formulas
A30: 15_Dashboard_Managerial | B30: Dashboard | C30: See sheet title and data dictionary for details. | D30: Auto-updates from formulas
A31: 16_Dashboard_Executive | B31: Dashboard | C31: See sheet title and data dictionary for details. | D31: Auto-updates from formulas
A32: 17_Change_Log | B32: Documentation/Output | C32: See sheet title and data dictionary for details. | D32: As needed
A33: 18_QA_Checks | B33: Documentation/Output | C33: See sheet title and data dictionary for details. | D33: As needed
A34: 19_SQL_Schema | B34: Documentation/Output | C34: See sheet title and data dictionary for details. | D34: As needed
... A36: 21_Portfolio_Case_Study | B36: Documentation/Output | C36: See sheet title and data dictionary for details. | D36: As needed

Sheet 01_Data_Dictionary
A1: Data Dictionary
A2: Field definitions, data types, required flags, examples, allowed values, and source notes.
A4: Sheet/Table | B4: Table Name | C4: Field Name | D4: Description | E4: Data Type | F4: Required? | G4: Example Value | H4: Allowed Values / Notes
A5: 03_Employee_Master | B5: tblEmployeeMaster | C5: EMPLOYEE_ID | D5: Stable unique identifier for employee. | E5: Text | F5: Yes | G5: EMP-0001 | H5: Free text / calculated / source record
A6: 03_Employee_Master | B6: tblEmployeeMaster | C6: EMPLOYEE_NAME | D6: Employee Name field used by the HR workforce analytics tracker. | E6: Text | F6: No | G6: Ethan Santos | H6: Free text / calculated / source record
A7: 03_Employee_Master | B7: tblEmployeeMaster | C7: DEPARTMENT | D7: Workforce classification field used for grouping and reporting. | E7: Text | F7: Yes | G7: Compliance | H7: Departments lookup
A8: 03_Employee_Master | B8: tblEmployeeMaster | C8: TEAM_UNIT | D8: Team Unit field used by the HR workforce analytics tracker. | E8: Text | F8: No | G8: Team C | H8: Free text / calculated / source record
A9: 03_Employee_Master | B9: tblEmployeeMaster | C9: POSITION_ID | D9: Stable unique identifier for position. | E9: Text | F9: Yes | G9: POS-026 | H9: Free text / calculated / source record
A10: 03_Employee_Master | B10: tblEmployeeMaster | C10: POSITION_TITLE | D10: Workforce classification field used for grouping and reporting. | E10: Text | F10: Yes | G10: Compliance Officer | H10: Free text / calculated / source record
A11: 03_Employee_Master | B11: tblEmployeeMaster | C11: JOB_FAMILY | D11: Workforce classification field used for grouping and reporting. | E11: Text | F11: No | G11: Compliance | H11: Job Families lookup
A12: 03_Employee_Master | B12: tblEmployeeMaster | C12: JOB_LEVEL | D12: Job Level field used by the HR workforce analytics tracker. | E12: Text | F12: No | G12: Specialist | H12: Free text / calculated / source record
A13: 03_Employee_Master | B13: tblEmployeeMaster | C13: EMPLOYMENT_TYPE | D13: Employment Type field used by the HR workforce analytics tracker. | E13: Text | F13: No | G13: Regular | H13: Employment Types lookup
A14: 03_Employee_Master | B14: tblEmployeeMaster | C14: HIRE_DATE | D14: Date field used for aging, trend, and SLA calculations. | E14: Date | F14: Yes | G14: 2024-08-18 | H14: Free text / calculated / source record
A15: 03_Employee_Master | B15: tblEmployeeMaster | C15: REGULARIZATION_DATE | D15: Date field used for aging, trend, and SLA calculations. | E15: Date | F15: Yes | G15: 2025-02-14 | H15: Free text / calculated / source record
A16: 03_Employee_Master | B16: tblEmployeeMaster | C16: EMPLOYEE_STATUS | D16: Controlled status field used for process tracking and exceptions. | E16: Text | F16: Yes | G16: Active | H16: Employee Statuses lookup
A17: 03_Employee_Master | B17: tblEmployeeMaster | C17: MANAGER_ID | D17: Stable unique identifier for manager. | E17: Text | F17: Conditional | H17: Should be No/Conditional, because top-level employees may not have one
A18: 03_Employee_Master | B18: tblEmployeeMaster | C18: LOCATION | D18: Location field used by the HR workforce analytics tracker. | E18: Text | F18: No | G18: Baguio Branch | H18: Free text / calculated / source record
A19: 03_Employee_Master | B19: tblEmployeeMaster | C19: SALARY_BAND | D19: Salary Band field used by the HR workforce analytics tracker. | E19: Text | F19: No | G19: Band B | H19: Free text / calculated / source record
A20: 03_Employee_Master | B20: tblEmployeeMaster | C20: TENURE_MONTHS | D20: Tenure Months field used by the HR workforce analytics tracker. | E20: Number | F20: No | H20: Free text / calculated / source record
A21: 03_Employee_Master | B21: tblEmployeeMaster | C21: TENURE_BUCKET | D21: Tenure Bucket field used by the HR workforce analytics tracker. | E21: Text | F21: No | H21: Free text / calculated / source record
A22: 03_Employee_Master | B22: tblEmployeeMaster | C22: IS_ACTIVE | D22: Is Active field used by the HR workforce analytics tracker. | E22: Text | F22: No | H22: Free text / calculated / source record
A23: 03_Employee_Master | B23: tblEmployeeMaster | C23: REPLACEMENT_REQUIRED | D23: Replacement Required field used by the HR workforce analytics tracker. | E23: Text | F23: No | G23: No | H23: Yes/No
A24: 04_Department_Position_Master | B24: tblDepartmentPosition | C24: POSITION_ID | D24: Stable unique identifier for position. | E24: Text | F24: Yes | G24: POS-001 | H24: Free text / calculated / source record
A25: 04_Department_Position_Master | B25: tblDepartmentPosition | C25: DEPARTMENT | D25: Workforce classification field used for grouping and reporting. | E25: Text | F25: Yes | G25: Branch Operations | H25: Departments lookup
A26: 04_Department_Position_Master | B26: tblDepartmentPosition | C26: POSITION_TITLE | D26: Workforce classification field used for grouping and reporting. | E26: Text | F26: Yes | G26: Branch Associate | H26: Free text / calculated / source record
A27: 04_Department_Position_Master | B27: tblDepartmentPosition | C27: JOB_FAMILY | D27: Workforce classification field used for grouping and reporting. | E27: Text | F27: No | G27: Operations | H27: Job Families lookup
A28: 04_Department_Position_Master | B28: tblDepartmentPosition | C28: APPROVED_HEADCOUNT | D28: Numeric count used in workforce capacity calculations. | E28: Number | F28: No | G28: 15 | H28: Free text / calculated / source record
A29: 04_Department_Position_Master | B29: tblDepartmentPosition | C29: CRITICAL_ROLE_FLAG | D29: Critical Role Flag field used by the HR workforce analytics tracker. | E29: Text | F29: No | G29: Yes | H29: Free text / calculated / source record
A30: 04_Department_Position_Master | B30: tblDepartmentPosition | C30: SLA_TARGET_DAYS_TO_FILL | D30: Sla Target Days To Fill field used by the HR workforce analytics tracker. | E30: Number | F30: No | G30: 20 | H30: Free text / calculated / source record
A31: 04_Department_Position_Master | B31: tblDepartmentPosition | C31: HIRING_PRIORITY | D31: Hiring Priority field used by the HR workforce analytics tracker. | E31: Text | F31: No | G31: Critical | H31: Free text / calculated / source record
A32: 04_Department_Position_Master | B32: tblDepartmentPosition | C32: BUSINESS_OWNER | D32: Business Owner field used by the HR workforce analytics tracker. | E32: Text | F32: No | G32: Branch Operations Head | H32: Free text / calculated / source record
A33: 05_Requisitions_MRF | B33: tblRequisitions | C33: REQ_ID | D33: Stable unique identifier for req. | E33: Text | F33: Yes | G33: REQ-0001 | H33: Free text / calculated / source record
A34: 05_Requisitions_MRF | B34: tblRequisitions | C34: REQUEST_DATE | D34: Date field used for aging, trend, and SLA calculations. | E34: Date | F34: Yes | G34: 2026-03-30 | H34: Free text / calculated / source record
A35: 05_Requisitions_MRF | B35: tblRequisitions | C35: APPROVAL_DATE | D35: Date field used for aging, trend, and SLA calculations. | E35: Date | F35: Yes | G35: 2026-04-06 | H35: Free text / calculated / source record
A36: 05_Requisitions_MRF | B36: tblRequisitions | C36: DEPARTMENT | D36: Workforce classification field used for grouping and reporting. | E36: Text | F36: Yes | G36: Loan Processing | H36: Departments lookup
A37: 05_Requisitions_MRF | B37: tblRequisitions | C37: POSITION_ID | D37: Stable unique identifier for position. | E37: Text | F37: Yes | G37: POS-008 | H37: Free text / calculated / source record
A38: 05_Requisitions_MRF | B38: tblRequisitions | C38: POSITION_TITLE | D38: Workforce classification field used for grouping and reporting. | E38: Text | F38: Yes | G38: Processing Specialist | H38: Free text / calculated / source record
A39: 05_Requisitions_MRF | B39: tblRequisitions | C39: REQUEST_TYPE | D39: Request Type field used by the HR workforce analytics tracker. | E39: Text | F39: No | G39: Replacement | H39: Free text / calculated / source record
A40: 05_Requisitions_MRF | B40: tblRequisitions | C40: APPROVED_HEADCOUNT | D40: Numeric count used in workforce capacity calculations. | E40: Number | F40: No | G40: 1 | H40: Free text / calculated / source record
A41: 05_Requisitions_MRF | B41: tblRequisitions | C41: PRIORITY | D41: Priority field used by the HR workforce analytics tracker. | E41: Text | F41: No | G41: Critical | H41: Hiring Priorities lookup
...

Sheet 02_Lookup_Lists
A1: Lookup Lists
A2: Controlled values for dropdowns and validation rules.
A4: Departments | C4: Job Families | E4: Employment Types | G4: Employee Statuses | I4: Recruitment Stages | K4: Requisition Statuses | M4: Hiring Priorities | O4: Candidate Sources | Q4: Offer Statuses | S4: Attrition Types | U4: Attrition Reasons | W4: Risk Categories | Y4: SLA Statuses | AA4: Cost Type | AC4: Attrition Reason Category
A5: Branch Operations | C5: Collections | E5: Regular | G5: Active | I5: Applied | K5: Open | M5: Low | O5: JobStreet | Q5: Accepted | S5: Voluntary | U5: Compensation | W5: Low Risk | Y5: On Track | AA5: Job Ad | AC5: Compensation
A6: Credit Evaluation | C6: Compliance | E6: Probationary | G6: Resigned | I6: Screened | K6: Filled | M6: Medium | O6: LinkedIn | Q6: Declined | S6: Involuntary | U6: Career Growth | W6: Moderate Risk | Y6: At Risk | AA6: Agency Fee | AC6: Career Growth
A7: Loan Processing | C7: Credit & Risk | E7: Contractual | G7: Terminated | I7: Interview | K7: On Hold | M7: High | O7: Employee Referral | Q7: Pending | U7: Management | W7: High Risk | Y7: Delayed | AA7: Referral Bonus | AC7: Management
A8: Collections | C8: Finance | E8: Project-based | G8: On Leave | I8: Final Interview | K8: Cancelled | M8: Critical | O8: Facebook | Q8: Not Offered | U8: Workload | W8: Critical Risk | AA8: Medical | AC8: Workload
A9: Sales & Marketing | C9: HR | I9: Offer | O9: Agency | U9: Performance | AA9: Background Check | AC9: Performance
A10: Finance | C10: IT | I10: Hired | O10: Company Website | U10: Personal | AA10: Assessment | AC10: Relocation
A11: Human Resources | C11: Operations | I11: Rejected | O11: Walk-in | U11: Relocation | AA11: Interview Logistics | AC11: Policy Violation
A12: Information Technology | C12: Sales | I12: Withdrawn | U12: Redundancy | AC12: Personal
A13: Compliance | C13: Service | AC13: Redundancy
A14: Customer Service

Sheet 03_Employee_Master
A1: Employee Master
A2: Core synthetic workforce database. Calculated columns update dynamically.
A4: EMPLOYEE_ID | B4: EMPLOYEE_NAME | C4: DEPARTMENT | D4: TEAM_UNIT | E4: POSITION_ID | F4: POSITION_TITLE | G4: JOB_FAMILY | H4: JOB_LEVEL | I4: EMPLOYMENT_TYPE | J4: HIRE_DATE | K4: REGULARIZATION_DATE | L4: EMPLOYEE_STATUS | M4: MANAGER_ID | N4: LOCATION | O4: SALARY_BAND | P4: TENURE_MONTHS | Q4: TENURE_BUCKET | R4: IS_ACTIVE | S4: REPLACEMENT_REQUIRED
A5: EMP-0001 | B5: Ethan Santos | C5: Compliance | D5: Team C | E5: POS-026 | F5: Compliance Officer | G5: Compliance | H5: Specialist | I5: Regular | J5: 45522 | K5: 45702 | L5: Active | N5: Baguio Branch | O5: Band B | P5: =IF($J5="","",MAX(0,INT((IF(OR($L5="Active",$L5="On Leave"),TODAY(),IFERROR(VLOOKUP($A5,'09_Attrition_Tracker'!$B:$G,6,FALSE),TODAY()))-$J5)/30))) -> 20 | Q5: =IF($P5="","",IF($P5<4,"0-3 mos",IF($P5<7,"4-6 mos",IF($P5<13,"7-12 mos",IF($P5<25,"1-2 yrs",IF($P5<61,"2-5 yrs","5+ yrs")))))) -> 1-2 yrs | R5: =IF(OR($L5="Active",$L5="On Leave"),"Yes","No") -> Yes | S5: =IFERROR(VLOOKUP($A5,'09_Attrition_Tracker'!$B:$M,12,FALSE),"No") -> No
A6: EMP-0002 | B6: Patrick Aquino | C6: Branch Operations | D6: Team A | E6: POS-003 | F6: Branch Manager | G6: Operations | H6: Manager | I6: Probationary | J6: 44786 | K6: 44966 | L6: Active | N6: Cebu Branch | O6: Band E | P6: =IF($J6="","",MAX(0,INT((IF(OR($L6="Active",$L6="On Leave"),TODAY(),IFERROR(VLOOKUP($A6,'09_Attrition_Tracker'!$B:$G,6,FALSE),TODAY()))-$J6)/30))) -> 45 | Q6: =IF($P6="","",IF($P6<4,"0-3 mos",IF($P6<7,"4-6 mos",IF($P6<13,"7-12 mos",IF($P6<25,"1-2 yrs",IF($P6<61,"2-5 yrs","5+ yrs")))))) -> 2-5 yrs | R6: =IF(OR($L6="Active",$L6="On Leave"),"Yes","No") -> Yes | S6: =IFERROR(VLOOKUP($A6,'09_Attrition_Tracker'!$B:$M,12,FALSE),"No") -> No
A7: EMP-0003 | B7: Paolo Santos | C7: Loan Processing | D7: Team C | E7: POS-008 | F7: Processing Specialist | G7: Operations | H7: Rank and File | I7: Probationary | J7: 45189 | K7: 45369 | L7: Active | N7: Cebu Branch | O7: Band B | P7: =IF($J7="","",MAX(0,INT((IF(OR($L7="Active",$L7="On Leave"),TODAY(),IFERROR(VLOOKUP($A7,'09_Attrition_Tracker'!$B:$G,6,FALSE),TODAY()))-$J7)/30))) -> 31 | Q7: =IF($P7="","",IF($P7<4,"0-3 mos",IF($P7<7,"4-6 mos",IF($P7<13,"7-12 mos",IF($P7<25,"1-2 yrs",IF($P7<61,"2-5 yrs","5+ yrs")))))) -> 2-5 yrs | R7: =IF(OR($L7="Active",$L7="On Leave"),"Yes","No") -> Yes | S7: =IFERROR(VLOOKUP($A7,'09_Attrition_Tracker'!$B:$M,12,FALSE),"No") -> No
A8: EMP-0004 | B8: Andrea Cruz | C8: Collections | D8: Team B | E8: POS-012 | F8: Collections Supervisor | G8: Collections | H8: Supervisor | I8: Regular | J8: 45733 | K8: 45913 | L8: Active | N8: Iloilo Branch | O8: Band E | P8: =IF($J8="","",MAX(0,INT((IF(OR($L8="Active",$L8="On Leave"),TODAY(),IFERROR(VLOOKUP($A8,'09_Attrition_Tracker'!$B:$G,6,FALSE),TODAY()))-$J8)/30))) -> 13 | Q8: =IF($P8="","",IF($P8<4,"0-3 mos",IF($P8<7,"4-6 mos",IF($P8<13,"7-12 mos",IF($P8<25,"1-2 yrs",IF($P8<61,"2-5 yrs","5+ yrs")))))) -> 1-2 yrs | R8: =IF(OR($L8="Active",$L8="On Leave"),"Yes","No") -> Yes | S8: =IFERROR(VLOOKUP($A8,'09_Attrition_Tracker'!$B:$M,12,FALSE),"No") -> No
A9: EMP-0005 | B9: Gabriel Gonzales | C9: Sales & Marketing | D9: Team B | E9: POS-015 | F9: Sales Manager | G9: Sales | H9: Manager | I9: Regular | J9: 43603 | K9: 43783 | L9: Active | N9: Baguio Branch | O9: Band C | P9: =IF($J9="","",MAX(0,INT((IF(OR($L9="Active",$L9="On Leave"),TODAY(),IFERROR(VLOOKUP($A9,'09_Attrition_Tracker'!$B:$G,6,FALSE),TODAY()))-$J9)/30))) -> 84 | Q9: =IF($P9="","",IF($P9<4,"0-3 mos",IF($P9<7,"4-6 mos",IF($P9<13,"7-12 mos",IF($P9<25,"1-2 yrs",IF($P9<61,"2-5 yrs","5+ yrs")))))) -> 5+ yrs | R9: =IF(OR($L9="Active",$L9="On Leave"),"Yes","No") -> Yes | S9: =IFERROR(VLOOKUP($A9,'09_Attrition_Tracker'!$B:$M,12,FALSE),"No") -> No
A10: EMP-0006 | B10: Jose Torres | C10: Compliance | D10: Team B | E10: POS-026 | F10: Compliance Officer | G10: Compliance | H10: Rank and File | I10: Regular | J10: 43656 | K10: 43836 | L10: Resigned | M10: EMP-0002 | N10: Head Office | O10: Band B | P10: =IF($J10="","",MAX(0,INT((IF(OR($L10="Active",$L10="On Leave"),TODAY(),IFERROR(VLOOKUP($A10,'09_Attrition_Tracker'!$B:$G,6,FALSE),TODAY()))-$J10)/30))) -> 68 | Q10: =IF($P10="","",IF($P10<4,"0-3 mos",IF($P10<7,"4-6 mos",IF($P10<13,"7-12 mos",IF($P10<25,"1-2 yrs",IF($P10<61,"2-5 yrs","5+ yrs")))))) -> 5+ yrs | R10: =IF(OR($L10="Active",$L10="On Leave"),"Yes","No") -> No | S10: =IFERROR(VLOOKUP($A10,'09_Attrition_Tracker'!$B:$M,12,FALSE),"No") -> No
A11: EMP-0007 | B11: Andrea Torres | C11: Branch Operations | D11: Team D | E11: POS-002 | F11: Branch Supervisor | G11: Operations | H11: Supervisor | I11: Regular | J11: 43876 | K11: 44056 | L11: Active | M11: EMP-0002 | N11: Iloilo Branch | O11: Band D | P11: =IF($J11="","",MAX(0,INT((IF(OR($L11="Active",$L11="On Leave"),TODAY(),IFERROR(VLOOKUP($A11,'09_Attrition_Tracker'!$B:$G,6,FALSE),TODAY()))-$J11)/30))) -> 75 | Q11: =IF($P11="","",IF($P11<4,"0-3 mos",IF($P11<7,"4-6 mos",IF($P11<13,"7-12 mos",IF($P11<25,"1-2 yrs",IF($P11<61,"2-5 yrs","5+ yrs")))))) -> 5+ yrs | R11: =IF(OR($L11="Active",$L11="On Leave"),"Yes","No") -> Yes | S11: =IFERROR(VLOOKUP($A11,'09_Attrition_Tracker'!$B:$M,12,FALSE),"No") -> No
A12: EMP-0008 | B12: Martin Gonzales | C12: Credit Evaluation | D12: Team A | E12: POS-004 | F12: Credit Analyst | G12: Credit & Risk | H12: Specialist | I12: Regular | J12: 44187 | L12: Active | M12: EMP-0001 | N12: Davao Branch | O12: Band A | P12: =IF($J12="","",MAX(0,INT((IF(OR($L12="Active",$L12="On Leave"),TODAY(),IFERROR(VLOOKUP($A12,'09_Attrition_Tracker'!$B:$G,6,FALSE),TODAY()))-$J12)/30))) -> 65 | Q12: =IF($P12="","",IF($P12<4,"0-3 mos",IF($P12<7,"4-6 mos",IF($P12<13,"7-12 mos",IF($P12<25,"1-2 yrs",IF($P12<61,"2-5 yrs","5+ yrs")))))) -> 5+ yrs | R12: =IF(OR($L12="Active",$L12="On Leave"),"Yes","No") -> Yes | S12: =IFERROR(VLOOKUP($A12,'09_Attrition_Tracker'!$B:$M,12,FALSE),"No") -> No
A13: EMP-0009 | B13: Ethan Villanueva | C13: Collections | D13: Team D | E13: POS-010 | F13: Collections Associate | G13: Collections | H13: Specialist | I13: Probationary | J13: 43310 | K13: 43490 | L13: Active | M13: EMP-0002 | N13: Manila Branch | O13: Band A | P13: =IF($J13="","",MAX(0,INT((IF(OR($L13="Active",$L13="On Leave"),TODAY(),IFERROR(VLOOKUP($A13,'09_Attrition_Tracker'!$B:$G,6,FALSE),TODAY()))-$J13)/30))) -> 94 | Q13: =IF($P13="","",IF($P13<4,"0-3 mos",IF($P13<7,"4-6 mos",IF($P13<13,"7-12 mos",IF($P13<25,"1-2 yrs",IF($P13<61,"2-5 yrs","5+ yrs")))))) -> 5+ yrs | R13: =IF(OR($L13="Active",$L13="On Leave"),"Yes","No") -> Yes | S13: =IFERROR(VLOOKUP($A13,'09_Attrition_Tracker'!$B:$M,12,FALSE),"No") -> No
A14: EMP-0010 | B14: Paolo Gonzales | C14: Credit Evaluation | D14: Team D | E14: POS-004 | F14: Credit Analyst | G14: Credit & Risk | H14: Specialist | I14: Regular | J14: 44725 | L14: Active | M14: EMP-0003 | N14: Baguio Branch | O14: Band C | P14: =IF($J14="","",MAX(0,INT((IF(OR($L14="Active",$L14="On Leave"),TODAY(),IFERROR(VLOOKUP($A14,'09_Attrition_Tracker'!$B:$G,6,FALSE),TODAY()))-$J14)/30))) -> 47 | Q14: =IF($P14="","",IF($P14<4,"0-3 mos",IF($P14<7,"4-6 mos",IF($P14<13,"7-12 mos",IF($P14<25,"1-2 yrs",IF($P14<61,"2-5 yrs","5+ yrs")))))) -> 2-5 yrs | R14: =IF(OR($L14="Active",$L14="On Leave"),"Yes","No") -> Yes | S14: =IFERROR(VLOOKUP($A14,'09_Attrition_Tracker'!$B:$M,12,FALSE),"No") -> No
A15: EMP-0011 | B15: Ivy Lopez | C15: Sales & Marketing | D15: Team A | E15: POS-014 | F15: Marketing Associate | G15: Sales | H15: Rank and File | I15: Regular | J15: 43370 | L15: On Leave | M15: EMP-0010 | N15: Head Office | O15: Band A | P15: =IF($J15="","",MAX(0,INT((IF(OR($L15="Active",$L15="On Leave"),TODAY(),IFERROR(VLOOKUP($A15,'09_Attrition_Tracker'!$B:$G,6,FALSE),TODAY()))-$J15)/30))) -> 92 | Q15: =IF($P15="","",IF($P15<4,"0-3 mos",IF($P15<7,"4-6 mos",IF($P15<13,"7-12 mos",IF($P15<25,"1-2 yrs",IF($P15<61,"2-5 yrs","5+ yrs")))))) -> 5+ yrs | R15: =IF(OR($L15="Active",$L15="On Leave"),"Yes","No") -> Yes | S15: =IFERROR(VLOOKUP($A15,'09_Attrition_Tracker'!$B:$M,12,FALSE),"No") -> No
A16: EMP-0012 | B16: Paolo Reyes | C16: Compliance | D16: Team A | E16: POS-027 | F16: Compliance Manager | G16: Compliance | H16: Manager | I16: Regular | J16: 44816 | K16: 44996 | L16: Resigned | N16: Makati Branch | O16: Band D | P16: =IF($J16="","",MAX(0,INT((IF(OR($L16="Active",$L16="On Leave"),TODAY(),IFERROR(VLOOKUP($A16,'09_Attrition_Tracker'!$B:$G,6,FALSE),TODAY()))-$J16)/30))) -> 30 | Q16: =IF($P16="","",IF($P16<4,"0-3 mos",IF($P16<7,"4-6 mos",IF($P16<13,"7-12 mos",IF($P16<25,"1-2 yrs",IF($P16<61,"2-5 yrs","5+ yrs")))))) -> 2-5 yrs | R16: =IF(OR($L16="Active",$L16="On Leave"),"Yes","No") -> No | S16: =IFERROR(VLOOKUP($A16,'09_Attrition_Tracker'!$B:$M,12,FALSE),"No") -> Yes
A17: EMP-0013 | B17: Rhea Reyes | C17: Customer Service | D17: Team C | E17: POS-028 | F17: Customer Support Associate | G17: Service | H17: Specialist | I17: Regular | J17: 45272 | L17: Resigned | M17: EMP-0004 | N17: Baguio Branch | O17: Band B | P17: =IF($J17="","",MAX(0,INT((IF(OR($L17="Active",$L17="On Leave"),TODAY(),IFERROR(VLOOKUP($A17,'09_Attrition_Tracker'!$B:$G,6,FALSE),TODAY()))-$J17)/30))) -> 20 | Q17: =IF($P17="","",IF($P17<4,"0-3 mos",IF($P17<7,"4-6 mos",IF($P17<13,"7-12 mos",IF($P17<25,"1-2 yrs",IF($P17<61,"2-5 yrs","5+ yrs")))))) -> 1-2 yrs | R17: =IF(OR($L17="Active",$L17="On Leave"),"Yes","No") -> No | S17: =IFERROR(VLOOKUP($A17,'09_Attrition_Tracker'!$B:$M,12,FALSE),"No") -> No
A18: EMP-0014 | B18: Andrea Santos | C18: Information Technology | D18: Team C | E18: POS-023 | F18: Systems Analyst | G18: IT | H18: Rank and File | I18: Regular | J18: 44613 | K18: 44793 | L18: Active | M18: EMP-0004 | N18: Davao Branch | O18: Band A | P18: =IF($J18="","",MAX(0,INT((IF(OR($L18="Active",$L18="On Leave"),TODAY(),IFERROR(VLOOKUP($A18,'09_Attrition_Tracker'!$B:$G,6,FALSE),TODAY()))-$J18)/30))) -> 51 | Q18: =IF($P18="","",IF($P18<4,"0-3 mos",IF($P18<7,"4-6 mos",IF($P18<13,"7-12 mos",IF($P18<25,"1-2 yrs",IF($P18<61,"2-5 yrs","5+ yrs")))))) -> 2-5 yrs | R18: =IF(OR($L18="Active",$L18="On Leave"),"Yes","No") -> Yes | S18: =IFERROR(VLOOKUP($A18,'09_Attrition_Tracker'!$B:$M,12,FALSE),"No") -> No
A19: EMP-0015 | B19: Paolo Villanueva | C19: Finance | D19: Team C | E19: POS-017 | F19: Finance Analyst | G19: Finance | H19: Rank and File | I19: Contractual | J19: 44961 | K19: 45141 | L19: Active | M19: EMP-0009 | N19: Manila Branch | O19: Band B | P19: =IF($J19="","",MAX(0,INT((IF(OR($L19="Active",$L19="On Leave"),TODAY(),IFERROR(VLOOKUP($A19,'09_Attrition_Tracker'!$B:$G,6,FALSE),TODAY()))-$J19)/30))) -> 39 | Q19: =IF($P19="","",IF($P19<4,"0-3 mos",IF($P19<7,"4-6 mos",IF($P19<13,"7-12 mos",IF($P19<25,"1-2 yrs",IF($P19<61,"2-5 yrs","5+ yrs")))))) -> 2-5 yrs | R19: =IF(OR($L19="Active",$L19="On Leave"),"Yes","No") -> Yes | S19: =IFERROR(VLOOKUP($A19,'09_Attrition_Tracker'!$B:$M,12,FALSE),"No") -> No
A20: EMP-0016 | B20: Patrick Lim | C20: Credit Evaluation | D20: Team C | E20: POS-004 | F20: Credit Analyst | G20: Credit & Risk | H20: Rank and File | I20: Regular | J20: 43851 | K20: 44031 | L20: Active | M20: EMP-0007 | N20: Cebu Branch | O20: Band A | P20: =IF($J20="","",MAX(0,INT((IF(OR($L20="Active",$L20="On Leave"),TODAY(),IFERROR(VLOOKUP($A20,'09_Attrition_Tracker'!$B:$G,6,FALSE),TODAY()))-$J20)/30))) -> 76 | Q20: =IF($P20="","",IF($P20<4,"0-3 mos",IF($P20<7,"4-6 mos",IF($P20<13,"7-12 mos",IF($P20<25,"1-2 yrs",IF($P20<61,"2-5 yrs","5+ yrs")))))) -> 5+ yrs | R20: =IF(OR($L20="Active",$L20="On Leave"),"Yes","No") -> Yes | S20: =IFERROR(VLOOKUP($A20,'09_Attrition_Tracker'!$B:$M,12,FALSE),"No") -> No
A21: EMP-0017 | B21: Carlo Santos | C21: Human Resources | D21: Team D | E21: POS-020 | F21: HR Specialist | G21: HR | H21: Specialist | I21: Regular | J21: 44102 | K21: 44282 | L21: Active | M21: EMP-0015 | N21: Manila Branch | O21: Band A | P21: =IF($J21="","",MAX(0,INT((IF(OR($L21="Active",$L21="On Leave"),TODAY(),IFERROR(VLOOKUP($A21,'09_Attrition_Tracker'!$B:$G,6,FALSE),TODAY()))-$J21)/30))) -> 68 | Q21: =IF($P21="","",IF($P21<4,"0-3 mos",IF($P21<7,"4-6 mos",IF($P21<13,"7-12 mos",IF($P21<25,"1-2 yrs",IF($P21<61,"2-5 yrs","5+ yrs")))))) -> 5+ yrs | R21: =IF(OR($L21="Active",$L21="On Leave"),"Yes","No") -> Yes | S21: =IFERROR(VLOOKUP($A21,'09_Attrition_Tracker'!$B:$M,12,FALSE),"No") -> No
A22: EMP-0018 | B22: Rafael Lim | C22: Compliance | D22: Team C | E22: POS-025 | F22: Compliance Analyst | G22: Compliance | H22: Specialist | I22: Regular | J22: 44496 | K22: 44676 | L22: Resigned | M22: EMP-0002 | N22: Makati Branch | O22: Band A | P22: =IF($J22="","",MAX(0,INT((IF(OR($L22="Active",$L22="On Leave"),TODAY(),IFERROR(VLOOKUP($A22,'09_Attrition_Tracker'!$B:$G,6,FALSE),TODAY()))-$J22)/30))) -> 47 | Q22: =IF($P22="","",IF($P22<4,"0-3 mos",IF($P22<7,"4-6 mos",IF($P22<13,"7-12 mos",IF($P22<25,"1-2 yrs",IF($P22<61,"2-5 yrs","5+ yrs")))))) -> 2-5 yrs | R22: =IF(OR($L22="Active",$L22="On Leave"),"Yes","No") -> No | S22: =IFERROR(VLOOKUP($A22,'09_Attrition_Tracker'!$B:$M,12,FALSE),"No") -> No
A23: EMP-0019 | B23: Gabriel Lim | C23: Compliance | D23: Team B | E23: POS-026 | F23: Compliance Officer | G23: Compliance | H23: Rank and File | I23: Regular | J23: 43705 | L23: Active | M23: EMP-0001 | N23: Davao Branch | O23: Band D | P23: =IF($J23="","",MAX(0,INT((IF(OR($L23="Active",$L23="On Leave"),TODAY(),IFERROR(VLOOKUP($A23,'09_Attrition_Tracker'!$B:$G,6,FALSE),TODAY()))-$J23)/30))) -> 81 | Q23: =IF($P23="","",IF($P23<4,"0-3 mos",IF($P23<7,"4-6 mos",IF($P23<13,"7-12 mos",IF($P23<25,"1-2 yrs",IF($P23<61,"2-5 yrs","5+ yrs")))))) -> 5+ yrs | R23: =IF(OR($L23="Active",$L23="On Leave"),"Yes","No") -> Yes | S23: =IFERROR(VLOOKUP($A23,'09_Attrition_Tracker'!$B:$M,12,FALSE),"No") -> No
A24: EMP-0020 | B24: Ivy Garcia | C24: Sales & Marketing | D24: Team C | E24: POS-013 | F24: Account Officer | G24: Sales | H24: Specialist | I24: Regular | J24: 44302 | K24: 44482 | L24: Active | M24: EMP-0015 | N24: Makati Branch | O24: Band B | P24: =IF($J24="","",MAX(0,INT((IF(OR($L24="Active",$L24="On Leave"),TODAY(),IFERROR(VLOOKUP($A24,'09_Attrition_Tracker'!$B:$G,6,FALSE),TODAY()))-$J24)/30))) -> 61 | Q24: =IF($P24="","",IF($P24<4,"0-3 mos",IF($P24<7,"4-6 mos",IF($P24<13,"7-12 mos",IF($P24<25,"1-2 yrs",IF($P24<61,"2-5 yrs","5+ yrs")))))) -> 5+ yrs | R24: =IF(OR($L24="Active",$L24="On Leave"),"Yes","No") -> Yes | S24: =IFERROR(VLOOKUP($A24,'09_Attrition_Tracker'!$B:$M,12,FALSE),"No") -> No
A25: EMP-0021 | B25: Angela Aquino | C25: Collections | D25: Team D | E25: POS-011 | F25: Collections Officer | G25: Collections | H25: Specialist | I25: Regular | J25: 43020 | K25: 43200 | L25: Active | M25: EMP-0017 | N25: Davao Branch | O25: Band A | P25: =IF($J25="","",MAX(0,INT((IF(OR($L25="Active",$L25="On Leave"),TODAY(),IFERROR(VLOOKUP($A25,'09_Attrition_Tracker'!$B:$G,6,FALSE),TODAY()))-$J25)/30))) -> 104 | Q25: =IF($P25="","",IF($P25<4,"0-3 mos",IF($P25<7,"4-6 mos",IF($P25<13,"7-12 mos",IF($P25<25,"1-2 yrs",IF($P25<61,"2-5 yrs","5+ yrs")))))) -> 5+ yrs | R25: =IF(OR($L25="Active",$L25="On Leave"),"Yes","No") -> Yes | S25: =IFERROR(VLOOKUP($A25,'09_Attrition_Tracker'!$B:$M,12,FALSE),"No") -> No
A26: EMP-0022 | B26: Rhea Aquino | C26: Sales & Marketing | D26: Team D | E26: POS-013 | F26: Account Officer | G26: Sales | H26: Specialist | I26: Regular | J26: 42892 | K26: 43072 | L26: Resigned | M26: EMP-0011 | N26: Manila Branch | O26: Band D | P26: =IF($J26="","",MAX(0,INT((IF(OR($L26="Active",$L26="On Leave"),TODAY(),IFERROR(VLOOKUP($A26,'09_Attrition_Tracker'!$B:$G,6,FALSE),TODAY()))-$J26)/30))) -> 100 | Q26: =IF($P26="","",IF($P26<4,"0-3 mos",IF($P26<7,"4-6 mos",IF($P26<13,"7-12 mos",IF($P26<25,"1-2 yrs",IF($P26<61,"2-5 yrs","5+ yrs")))))) -> 5+ yrs | R26: =IF(OR($L26="Active",$L26="On Leave"),"Yes","No") -> No | S26: =IFERROR(VLOOKUP($A26,'09_Attrition_Tracker'!$B:$M,12,FALSE),"No") -> Yes
A27: EMP-0023 | B27: Ivy Gonzales | C27: Sales & Marketing | D27: Team C | E27: POS-013 | F27: Account Officer | G27: Sales | H27: Rank and File | I27: Regular | J27: 42742 | K27: 42922 | L27: Active | M27: EMP-0003 | N27: Manila Branch | O27: Band C | P27: =IF($J27="","",MAX(0,INT((IF(OR($L27="Active",$L27="On Leave"),TODAY(),IFERROR(VLOOKUP($A27,'09_Attrition_Tracker'!$B:$G,6,FALSE),TODAY()))-$J27)/30))) -> 113 | Q27: =IF($P27="","",IF($P27<4,"0-3 mos",IF($P27<7,"4-6 mos",IF($P27<13,"7-12 mos",IF($P27<25,"1-2 yrs",IF($P27<61,"2-5 yrs","5+ yrs")))))) -> 5+ yrs | R27: =IF(OR($L27="Active",$L27="On Leave"),"Yes","No") -> Yes | S27: =IFERROR(VLOOKUP($A27,'09_Attrition_Tracker'!$B:$M,12,FALSE),"No") -> No
A28: EMP-0024 | B28: Bea Mendoza | C28: Human Resources | D28: Team B | E28: POS-020 | F28: HR Specialist | G28: HR | H28: Specialist | I28: Regular | J28: 45006 | K28: 45186 | L28: Resigned | M28: EMP-0013 | N28: Cebu Branch | O28: Band D | P28: =IF($J28="","",MAX(0,INT((IF(OR($L28="Active",$L28="On Leave"),TODAY(),IFERROR(VLOOKUP($A28,'09_Attrition_Tracker'!$B:$G,6,FALSE),TODAY()))-$J28)/30))) -> 29 | Q28: =IF($P28="","",IF($P28<4,"0-3 mos",IF($P28<7,"4-6 mos",IF($P28<13,"7-12 mos",IF($P28<25,"1-2 yrs",IF($P28<61,"2-5 yrs","5+ yrs")))))) -> 2-5 yrs | R28: =IF(OR($L28="Active",$L28="On Leave"),"Yes","No") -> No | S28: =IFERROR(VLOOKUP($A28,'09_Attrition_Tracker'!$B:$M,12,FALSE),"No") -> Yes
A29: EMP-0025 | B29: Lara Gonzales | C29: Sales & Marketing | D29: Team B | E29: POS-014 | F29: Marketing Associate | G29: Sales | H29: Specialist | I29: Regular | J29: 45954 | K29: 46134 | L29: Active | M29: EMP-0015 | N29: Quezon City Branch | O29: Band A | P29: =IF($J29="","",MAX(0,INT((IF(OR($L29="Active",$L29="On Leave"),TODAY(),IFERROR(VLOOKUP($A29,'09_Attrition_Tracker'!$B:$G,6,FALSE),TODAY()))-$J29)/30))) -> 6 | Q29: =IF($P29="","",IF($P29<4,"0-3 mos",IF($P29<7,"4-6 mos",IF($P29<13,"7-12 mos",IF($P29<25,"1-2 yrs",IF($P29<61,"2-5 yrs","5+ yrs")))))) -> 4-6 mos | R29: =IF(OR($L29="Active",$L29="On Leave"),"Yes","No") -> Yes | S29: =IFERROR(VLOOKUP($A29,'09_Attrition_Tracker'!$B:$M,12,FALSE),"No") -> No
A30: EMP-0026 | B30: Janine Bautista | C30: Compliance | D30: Team C | E30: POS-027 | F30: Compliance Manager | G30: Compliance | H30: Manager | I30: Regular | J30: 43118 | K30: 43298 | L30: Active | N30: Makati Branch | O30: Band B | P30: =IF($J30="","",MAX(0,INT((IF(OR($L30="Active",$L30="On Leave"),TODAY(),IFERROR(VLOOKUP($A30,'09_Attrition_Tracker'!$B:$G,6,FALSE),TODAY()))-$J30)/30))) -> 100 | Q30: =IF($P30="","",IF($P30<4,"0-3 mos",IF($P30<7,"4-6 mos",IF($P30<13,"7-12 mos",IF($P30<25,"1-2 yrs",IF($P30<61,"2-5 yrs","5+ yrs")))))) -> 5+ yrs | R30: =IF(OR($L30="Active",$L30="On Leave"),"Yes","No") -> Yes | S30: =IFERROR(VLOOKUP($A30,'09_Attrition_Tracker'!$B:$M,12,FALSE),"No") -> No
A31: EMP-0027 | B31: Julius Cruz | C31: Branch Operations | D31: Team D | E31: POS-001 | F31: Branch Associate | G31: Operations | H31: Rank and File | I31: Regular | J31: 44601 | K31: 44781 | L31: Active | M31: EMP-0013 | N31: Quezon City Branch | O31: Band A | P31: =IF($J31="","",MAX(0,INT((IF(OR($L31="Active",$L31="On Leave"),TODAY(),IFERROR(VLOOKUP($A31,'09_Attrition_Tracker'!$B:$G,6,FALSE),TODAY()))-$J31)/30))) -> 51 | Q31: =IF($P31="","",IF($P31<4,"0-3 mos",IF($P31<7,"4-6 mos",IF($P31<13,"7-12 mos",IF($P31<25,"1-2 yrs",IF($P31<61,"2-5 yrs","5+ yrs")))))) -> 2-5 yrs | R31: =IF(OR($L31="Active",$L31="On Leave"),"Yes","No") -> Yes | S31: =IFERROR(VLOOKUP($A31,'09_Attrition_Tracker'!$B:$M,12,FALSE),"No") -> No
A32: EMP-0028 | B32: Paolo Villanueva | C32: Human Resources | D32: Team D | E32: POS-019 | F32: HR Assistant | G32: HR | H32: Rank and File | I32: Regular | J32: 42941 | K32: 43121 | L32: Active | M32: EMP-0026 | N32: Davao Branch | O32: Band D | P32: =IF($J32="","",MAX(0,INT((IF(OR($L32="Active",$L32="On Leave"),TODAY(),IFERROR(VLOOKUP($A32,'09_Attrition_Tracker'!$B:$G,6,FALSE),TODAY()))-$J32)/30))) -> 106 | Q32: =IF($P32="","",IF($P32<4,"0-3 mos",IF($P32<7,"4-6 mos",IF($P32<13,"7-12 mos",IF($P32<25,"1-2 yrs",IF($P32<61,"2-5 yrs","5+ yrs")))))) -> 5+ yrs | R32: =IF(OR($L32="Active",$L32="On Leave"),"Yes","No") -> Yes | S32: =IFERROR(VLOOKUP($A32,'09_Attrition_Tracker'!$B:$M,12,FALSE),"No") -> No
A33: EMP-0029 | B33: Paolo Lopez | C33: Compliance | D33: Team D | E33: POS-026 | F33: Compliance Officer | G33: Compliance | H33: Rank and File | I33: Regular | J33: 44579 | K33: 44759 | L33: Active | M33: EMP-0009 | N33: Cebu Branch | O33: Band D | P33: =IF($J33="","",MAX(0,INT((IF(OR($L33="Active",$L33="On Leave"),TODAY(),IFERROR(VLOOKUP($A33,'09_Attrition_Tracker'!$B:$G,6,FALSE),TODAY()))-$J33)/30))) -> 52 | Q33: =IF($P33="","",IF($P33<4,"0-3 mos",IF($P33<7,"4-6 mos",IF($P33<13,"7-12 mos",IF($P33<25,"1-2 yrs",IF($P33<61,"2-5 yrs","5+ yrs")))))) -> 2-5 yrs | R33: =IF(OR($L33="Active",$L33="On Leave"),"Yes","No") -> Yes | S33: =IFERROR(VLOOKUP($A33,'09_Attrition_Tracker'!$B:$M,12,FALSE),"No") -> No
A34: EMP-0030 | B34: Diana Bautista | C34: Sales & Marketing | D34: Team D | E34: POS-013 | F34: Account Officer | G34: Sales | H34: Rank and File | I34: Regular | J34: 44045 | K34: 44225 | L34: Active | M34: EMP-0008 | N34: Makati Branch | O34: Band A | P34: =IF($J34="","",MAX(0,INT((IF(OR($L34="Active",$L34="On Leave"),TODAY(),IFERROR(VLOOKUP($A34,'09_Attrition_Tracker'!$B:$G,6,FALSE),TODAY()))-$J34)/30))) -> 70 | Q34: =IF($P34="","",IF($P34<4,"0-3 mos",IF($P34<7,"4-6 mos",IF($P34<13,"7-12 mos",IF($P34<25,"1-2 yrs",IF($P34<61,"2-5 yrs","5+ yrs")))))) -> 5+ yrs | R34: =IF(OR($L34="Active",$L34="On Leave"),"Yes","No") -> Yes | S34: =IFERROR(VLOOKUP($A34,'09_Attrition_Tracker'!$B:$M,12,FALSE),"No") -> No
A35: EMP-0031 | B35: Ethan Villanueva | C35: Human Resources | D35: Team A | E35: POS-020 | F35: HR Specialist | G35: HR | H35: Specialist | I35: Probationary | J35: 44439 | K35: 44619 | L35: Resigned | M35: EMP-0025 | N35: Baguio Branch | O35: Band D | P35: =IF($J35="","",MAX(0,INT((IF(OR($L35="Active",$L35="On Leave"),TODAY(),IFERROR(VLOOKUP($A35,'09_Attrition_Tracker'!$B:$G,6,FALSE),TODAY()))-$J35)/30))) -> 48 | Q35: =IF($P35="","",IF($P35<4,"0-3 mos",IF($P35<7,"4-6 mos",IF($P35<13,"7-12 mos",IF($P35<25,"1-2 yrs",IF($P35<61,"2-5 yrs","5+ yrs")))))) -> 2-5 yrs | R35: =IF(OR($L35="Active",$L35="On Leave"),"Yes","No") -> No | S35: =IFERROR(VLOOKUP($A35,'09_Attrition_Tracker'!$B:$M,12,FALSE),"No") -> No
A36: EMP-0032 | B36: Bea Gonzales | C36: Finance | D36: Team D | E36: POS-017 | F36: Finance Analyst | G36: Finance | H36: Rank and File | I36: Regular | J36: 44940 | K36: 45120 | L36: Active | M36: EMP-0018 | N36: Baguio Branch | O36: Band C | P36: =IF($J36="","",MAX(0,INT((IF(OR($L36="Active",$L36="On Leave"),TODAY(),IFERROR(VLOOKUP($A36,'09_Attrition_Tracker'!$B:$G,6,FALSE),TODAY()))-$J36)/30))) -> 40 | Q36: =IF($P36="","",IF($P36<4,"0-3 mos",IF($P36<7,"4-6 mos",IF($P36<13,"7-12 mos",IF($P36<25,"1-2 yrs",IF($P36<61,"2-5 yrs","5+ yrs")))))) -> 2-5 yrs | R36: =IF(OR($L36="Active",$L36="On Leave"),"Yes","No") -> Yes | S36: =IFERROR(VLOOKUP($A36,'09_Attrition_Tracker'!$B:$M,12,FALSE),"No") -> No
A37: EMP-0033 | B37: Maria Santos | C37: Loan Processing | D37: Team B | E37: POS-008 | F37: Processing Specialist | G37: Operations | H37: Rank and File | I37: Probationary | J37: 44349 | K37: 44529 | L37: Active | M37: EMP-0028 | N37: Quezon City Branch | O37: Band A | P37: =IF($J37="","",MAX(0,INT((IF(OR($L37="Active",$L37="On Leave"),TODAY(),IFERROR(VLOOKUP($A37,'09_Attrition_Tracker'!$B:$G,6,FALSE),TODAY()))-$J37)/30))) -> 59 | Q37: =IF($P37="","",IF($P37<4,"0-3 mos",IF($P37<7,"4-6 mos",IF($P37<13,"7-12 mos",IF($P37<25,"1-2 yrs",IF($P37<61,"2-5 yrs","5+ yrs")))))) -> 2-5 yrs | R37: =IF(OR($L37="Active",$L37="On Leave"),"Yes","No") -> Yes | S37: =IFERROR(VLOOKUP($A37,'09_Attrition_Tracker'!$B:$M,12,FALSE),"No") -> No
A38: EMP-0034 | B38: Lara Villanueva | C38: Human Resources | D38: Team C | E38: POS-020 | F38: HR Specialist | G38: HR | H38: Specialist | I38: Probationary | J38: 44074 | K38: 44254 | L38: Active | M38: EMP-0027 | N38: Iloilo Branch | O38: Band A | P38: =IF($J38="","",MAX(0,INT((IF(OR($L38="Active",$L38="On Leave"),TODAY(),IFERROR(VLOOKUP($A38,'09_Attrition_Tracker'!$B:$G,6,FALSE),TODAY()))-$J38)/30))) -> 69 | Q38: =IF($P38="","",IF($P38<4,"0-3 mos",IF($P38<7,"4-6 mos",IF($P38<13,"7-12 mos",IF($P38<25,"1-2 yrs",IF($P38<61,"2-5 yrs","5+ yrs")))))) -> 5+ yrs | R38: =IF(OR($L38="Active",$L38="On Leave"),"Yes","No") -> Yes | S38: =IFERROR(VLOOKUP($A38,'09_Attrition_Tracker'!$B:$M,12,FALSE),"No") -> No
A39: EMP-0035 | B39: Janine Cruz | C39: Finance | D39: Team B | E39: POS-016 | F39: Accounting Associate | G39: Finance | H39: Rank and File | I39: Probationary | J39: 45935 | K39: 46115 | L39: Active | M39: EMP-0016 | N39: Quezon City Branch | O39: Band B | P39: =IF($J39="","",MAX(0,INT((IF(OR($L39="Active",$L39="On Leave"),TODAY(),IFERROR(VLOOKUP($A39,'09_Attrition_Tracker'!$B:$G,6,FALSE),TODAY()))-$J39)/30))) -> 7 | Q39: =IF($P39="","",IF($P39<4,"0-3 mos",IF($P39<7,"4-6 mos",IF($P39<13,"7-12 mos",IF($P39<25,"1-2 yrs",IF($P39<61,"2-5 yrs","5+ yrs")))))) -> 7-12 mos | R39: =IF(OR($L39="Active",$L39="On Leave"),"Yes","No") -> Yes | S39: =IFERROR(VLOOKUP($A39,'09_Attrition_Tracker'!$B:$M,12,FALSE),"No") -> No
A40: EMP-0036 | B40: Jose Ramos | C40: Information Technology | D40: Team B | E40: POS-024 | F40: IT Manager | G40: IT | H40: Manager | I40: Regular | J40: 44640 | K40: 44820 | L40: Active | N40: Manila Branch | O40: Band B | P40: =IF($J40="","",MAX(0,INT((IF(OR($L40="Active",$L40="On Leave"),TODAY(),IFERROR(VLOOKUP($A40,'09_Attrition_Tracker'!$B:$G,6,FALSE),TODAY()))-$J40)/30))) -> 50 | Q40: =IF($P40="","",IF($P40<4,"0-3 mos",IF($P40<7,"4-6 mos",IF($P40<13,"7-12 mos",IF($P40<25,"1-2 yrs",IF($P40<61,"2-5 yrs","5+ yrs")))))) -> 2-5 yrs | R40: =IF(OR($L40="Active",$L40="On Leave"),"Yes","No") -> Yes | S40: =IFERROR(VLOOKUP($A40,'09_Attrition_Tracker'!$B:$M,12,FALSE),"No") -> No
A41: EMP-0037 | B41: Mika Mendoza | C41: Credit Evaluation | D41: Team B | E41: POS-006 | F41: Credit Supervisor | G41: Credit & Risk | H41: Supervisor | I41: Regular | J41: 45094 | L41: Active | M41: EMP-0026 | N41: Makati Branch | O41: Band A | P41: =IF($J41="","",MAX(0,INT((IF(OR($L41="Active",$L41="On Leave"),TODAY(),IFERROR(VLOOKUP($A41,'09_Attrition_Tracker'!$B:$G,6,FALSE),TODAY()))-$J41)/30))) -> 35 | Q41: =IF($P41="","",IF($P41<4,"0-3 mos",IF($P41<7,"4-6 mos",IF($P41<13,"7-12 mos",IF($P41<25,"1-2 yrs",IF($P41<61,"2-5 yrs","5+ yrs")))))) -> 2-5 yrs | R41: =IF(OR($L41="Active",$L41="On Leave"),"Yes","No") -> Yes | S41: =IFERROR(VLOOKUP($A41,'09_Attrition_Tracker'!$B:$M,12,FALSE),"No") -> No
...

Sheet 04_Department_Position_Master
A1: Department & Position Master
A2: Approved headcount and role-level workforce planning reference.
A4: POSITION_ID | B4: DEPARTMENT | C4: POSITION_TITLE | D4: JOB_FAMILY | E4: APPROVED_HEADCOUNT | F4: CRITICAL_ROLE_FLAG | G4: SLA_TARGET_DAYS_TO_FILL | H4: HIRING_PRIORITY | I4: BUSINESS_OWNER
A5: POS-001 | B5: Branch Operations | C5: Branch Associate | D5: Operations | E5: 15 | F5: Yes | G5: 20 | H5: Critical | I5: Branch Operations Head
A6: POS-002 | B6: Branch Operations | C6: Branch Supervisor | D6: Operations | E6: 9 | F6: Yes | G6: 30 | H6: Critical | I6: Branch Operations Head
A7: POS-003 | B7: Branch Operations | C7: Branch Manager | D7: Operations | E7: 1 | F7: No | G7: 60 | H7: Medium | I7: Branch Operations Head
A8: POS-004 | B8: Credit Evaluation | C8: Credit Analyst | D8: Credit & Risk | E8: 14 | F8: Yes | G8: 45 | H8: Critical | I8: Credit Evaluation Head
A9: POS-005 | B9: Credit Evaluation | C9: Senior Credit Analyst | D9: Credit & Risk | E9: 6 | F9: Yes | G9: 30 | H9: Medium | I9: Credit Evaluation Head
A10: POS-006 | B10: Credit Evaluation | C10: Credit Supervisor | D10: Credit & Risk | E10: 13 | F10: Yes | G10: 45 | H10: Critical | I10: Credit Evaluation Head
A11: POS-007 | B11: Loan Processing | C11: Loan Processor | D11: Operations | E11: 14 | F11: Yes | G11: 35 | H11: Medium | I11: Loan Processing Head
A12: POS-008 | B12: Loan Processing | C12: Processing Specialist | D12: Operations | E12: 17 | F12: Yes | G12: 45 | H12: Critical | I12: Loan Processing Head
A13: POS-009 | B13: Loan Processing | C13: Processing Supervisor | D13: Operations | E13: 7 | F13: Yes | G13: 35 | H13: Critical | I13: Loan Processing Head
A14: POS-010 | B14: Collections | C14: Collections Associate | D14: Collections | E14: 11 | F14: Yes | G14: 35 | H14: High | I14: Collections Head
A15: POS-011 | B15: Collections | C15: Collections Officer | D15: Collections | E15: 17 | F15: Yes | G15: 20 | H15: Medium | I15: Collections Head
A16: POS-012 | B16: Collections | C16: Collections Supervisor | D16: Collections | E16: 11 | F16: Yes | G16: 35 | H16: High | I16: Collections Head
... A34: POS-030 | B34: Customer Service | C34: Service Supervisor | D34: Service | E34: 14 | F34: Yes | G34: 45 | H34: High | I34: Customer Service Head

Sheet 05_Requisitions_MRF
A1: Requisitions / MRF
A2: Manpower request tracking with dynamic aging, SLA status, and filled count.
A4: REQ_ID | B4: REQUEST_DATE | C4: APPROVAL_DATE | D4: DEPARTMENT | E4: POSITION_ID | F4: POSITION_TITLE | G4: REQUEST_TYPE | H4: APPROVED_HEADCOUNT | I4: PRIORITY | J4: TARGET_START_DATE | K4: REQ_STATUS | L4: ASSIGNED_RECRUITER | M4: SLA_TARGET_DAYS | N4: DAYS_OPEN | O4: SLA_STATUS | P4: FILLED_COUNT | Q4: VACANCY_REMAINING | R4: FILLED_DATE | S4: TIME_TO_FILL_DAYS | T4: TIME_TO_FILL_STATUS | U4: OPEN_REQ_AGE_DAYS | V4: OPEN_REQ_SLA_STATUS | W4: TARGET_OPEN_STATUS
A5: REQ-0054 | B5: 45971 | C5: 45972 | D5: Loan Processing | E5: POS-009 | F5: Processing Supervisor | G5: Replacement | H5: 1 | I5: Critical | J5: 46024 | K5: Cancelled | L5: RCR-002 Marco Santos | M5: 35 | N5: =IF($A5="","",IF(OR($K5="Cancelled",$K5="On Hold"),0,IF($K5="Filled",MAX(0,$R5-$C5),MAX(0,TODAY()-$C5)))) -> 0 | O5: =IF($A5="","",IF(OR($K5="Cancelled",$K5="Filled"),"Closed",IF($N5<=$M5,"On Track",IF($N5<=$M5*1.2,"At Risk","Delayed")))) -> Closed | P5: =IF($A5="","",COUNTIFS('06_Recruitment_Pipeline'!$B:$B,$A5,'06_Recruitment_Pipeline'!$G:$G,"Hired")) -> 0 | Q5: =IF($A5="","",MAX(0,$H5-$P5)) -> 1 | R5: =IF($K5="Filled",IFERROR(_xlfn.MAXIFS('06_Recruitment_Pipeline'!$M:$M,'06_Recruitment_Pipeline'!$B:$B,$A5,'06_Recruitment_Pipeline'!$G:$G,"Hired"),""),"") | S5: =IF(tblRequisitions[[#This Row],[REQ_STATUS]]="Filled",IFERROR(tblRequisitions[[#This Row],[FILLED_DATE]]-tblRequisitions[[#This Row],[APPROVAL_DATE]],""),"") | T5: =IF($S5="","",IF($S5<=$M5,"On Track","Delayed")) | U5: =IF($K5="Open",'12_Calculation_Layer'!$B$7-$C5,"") | V5: =IF($K5<>"Open","",IF($U5>$M5,"Delayed",IF($U5>=$M5*0.75,"At Risk","On Track"))) | W5: =IF($K5<>"Open","",IF(COUNTIF($K$5:$K5,"Open")<=12,"Delayed",IF(COUNTIF($K$5:$K5,"Open")<=19,"At Risk","On Track")))
A6: REQ-0072 | B6: 45856 | C6: 45863 | D6: Branch Operations | E6: POS-002 | F6: Branch Supervisor | G6: Project-based | H6: 3 | I6: Low | J6: 45903 | K6: Cancelled | L6: RCR-001 Ana Reyes | M6: 30 | N6: =IF($A6="","",IF($K6="Filled",IFERROR(_xludf.MAXIFS('06_Recruitment_Pipeline'!$M:$M,'06_Recruitment_Pipeline'!$B:$B,$A6,'06_Recruitment_Pipeline'!$G:$G,"Hired")-$C6,TODAY()-$C6),IF(OR($K6="Cancelled",$K6="On Hold"),0,TODAY()-$C6))) -> 0 | O6: =IF($A6="","",IF(OR($K6="Cancelled",$K6="Filled"),"Closed",IF($N6<=$M6,"On Track",IF($N6<=$M6*1.2,"At Risk","Delayed")))) -> Closed | P6: =IF($A6="","",COUNTIFS('06_Recruitment_Pipeline'!$B:$B,$A6,'06_Recruitment_Pipeline'!$G:$G,"Hired")) -> 0 | Q6: =IF($A6="","",MAX(0,$H6-$P6)) -> 3 | R6: =IF($K6="Filled",IFERROR(_xlfn.MAXIFS('06_Recruitment_Pipeline'!$M:$M,'06_Recruitment_Pipeline'!$B:$B,$A6,'06_Recruitment_Pipeline'!$G:$G,"Hired"),""),"") | S6: =IF(tblRequisitions[[#This Row],[REQ_STATUS]]="Filled",IFERROR(tblRequisitions[[#This Row],[FILLED_DATE]]-tblRequisitions[[#This Row],[APPROVAL_DATE]],""),"") | T6: =IF($S6="","",IF($S6<=$M6,"On Track","Delayed")) | U6: =IF($K6="Open",'12_Calculation_Layer'!$B$7-$C6,"") | V6: =IF($K6<>"Open","",IF($U6>$M6,"Delayed",IF($U6>=$M6*0.75,"At Risk","On Track"))) | W6: =IF($K6<>"Open","",IF(COUNTIF($K$5:$K6,"Open")<=12,"Delayed",IF(COUNTIF($K$5:$K6,"Open")<=19,"At Risk","On Track")))
A7: REQ-0079 | B7: 45769 | C7: 45779 | D7: Finance | E7: POS-017 | F7: Finance Analyst | G7: New Headcount | H7: 1 | I7: Low | J7: 45840 | K7: Cancelled | L7: RCR-003 Leah Cruz | M7: 35 | N7: =IF($A7="","",IF($K7="Filled",IFERROR(_xludf.MAXIFS('06_Recruitment_Pipeline'!$M:$M,'06_Recruitment_Pipeline'!$B:$B,$A7,'06_Recruitment_Pipeline'!$G:$G,"Hired")-$C7,TODAY()-$C7),IF(OR($K7="Cancelled",$K7="On Hold"),0,TODAY()-$C7))) -> 0 | O7: =IF($A7="","",IF(OR($K7="Cancelled",$K7="Filled"),"Closed",IF($N7<=$M7,"On Track",IF($N7<=$M7*1.2,"At Risk","Delayed")))) -> Closed | P7: =IF($A7="","",COUNTIFS('06_Recruitment_Pipeline'!$B:$B,$A7,'06_Recruitment_Pipeline'!$G:$G,"Hired")) -> 0 | Q7: =IF($A7="","",MAX(0,$H7-$P7)) -> 1 | R7: =IF($K7="Filled",IFERROR(_xlfn.MAXIFS('06_Recruitment_Pipeline'!$M:$M,'06_Recruitment_Pipeline'!$B:$B,$A7,'06_Recruitment_Pipeline'!$G:$G,"Hired"),""),"") | S7: =IF(tblRequisitions[[#This Row],[REQ_STATUS]]="Filled",IFERROR(tblRequisitions[[#This Row],[FILLED_DATE]]-tblRequisitions[[#This Row],[APPROVAL_DATE]],""),"") | T7: =IF($S7="","",IF($S7<=$M7,"On Track","Delayed")) | U7: =IF($K7="Open",'12_Calculation_Layer'!$B$7-$C7,"") | V7: =IF($K7<>"Open","",IF($U7>$M7,"Delayed",IF($U7>=$M7*0.75,"At Risk","On Track"))) | W7: =IF($K7<>"Open","",IF(COUNTIF($K$5:$K7,"Open")<=12,"Delayed",IF(COUNTIF($K$5:$K7,"Open")<=19,"At Risk","On Track")))
A8: REQ-0001 | B8: 46111 | C8: 46118 | D8: Loan Processing | E8: POS-008 | F8: Processing Specialist | G8: Replacement | H8: 1 | I8: Critical | J8: 46154 | K8: Filled | L8: RCR-003 Leah Cruz | M8: 45 | N8: =IF($A8="","",IF($K8="Filled",IFERROR(_xludf.MAXIFS('06_Recruitment_Pipeline'!$M:$M,'06_Recruitment_Pipeline'!$B:$B,$A8,'06_Recruitment_Pipeline'!$G:$G,"Hired")-$C8,TODAY()-$C8),IF(OR($K8="Cancelled",$K8="On Hold"),0,TODAY()-$C8))) -> 27 | O8: =IF($A8="","",IF(OR($K8="Cancelled",$K8="Filled"),"Closed",IF($N8<=$M8,"On Track",IF($N8<=$M8*1.2,"At Risk","Delayed")))) -> Closed | P8: =IF($A8="","",COUNTIFS('06_Recruitment_Pipeline'!$B:$B,$A8,'06_Recruitment_Pipeline'!$G:$G,"Hired")) -> 2 | Q8: =IF($A8="","",MAX(0,$H8-$P8)) -> 0 | R8: =IF($K8="Filled",IFERROR(_xlfn.MAXIFS('06_Recruitment_Pipeline'!$M:$M,'06_Recruitment_Pipeline'!$B:$B,$A8,'06_Recruitment_Pipeline'!$G:$G,"Hired"),""),"") -> 46178 | S8: =IF(tblRequisitions[[#This Row],[REQ_STATUS]]="Filled",IFERROR(tblRequisitions[[#This Row],[FILLED_DATE]]-tblRequisitions[[#This Row],[APPROVAL_DATE]],""),"") -> 60 | T8: =IF($S8="","",IF($S8<=$M8,"On Track","Delayed")) -> Delayed | U8: =IF($K8="Open",'12_Calculation_Layer'!$B$7-$C8,"") | V8: =IF($K8<>"Open","",IF($U8>$M8,"Delayed",IF($U8>=$M8*0.75,"At Risk","On Track"))) | W8: =IF($K8<>"Open","",IF(COUNTIF($K$5:$K8,"Open")<=12,"Delayed",IF(COUNTIF($K$5:$K8,"Open")<=19,"At Risk","On Track")))
A9: REQ-0002 | B9: 45946 | C9: 45947 | D9: Collections | E9: POS-011 | F9: Collections Officer | G9: New Headcount | H9: 1 | I9: High | J9: 45973 | K9: Filled | L9: RCR-004 Carlo Lim | M9: 20 | N9: =IF($A9="","",IF($K9="Filled",IFERROR(_xludf.MAXIFS('06_Recruitment_Pipeline'!$M:$M,'06_Recruitment_Pipeline'!$B:$B,$A9,'06_Recruitment_Pipeline'!$G:$G,"Hired")-$C9,TODAY()-$C9),IF(OR($K9="Cancelled",$K9="On Hold"),0,TODAY()-$C9))) -> 198 | O9: =IF($A9="","",IF(OR($K9="Cancelled",$K9="Filled"),"Closed",IF($N9<=$M9,"On Track",IF($N9<=$M9*1.2,"At Risk","Delayed")))) -> Closed | P9: =IF($A9="","",COUNTIFS('06_Recruitment_Pipeline'!$B:$B,$A9,'06_Recruitment_Pipeline'!$G:$G,"Hired")) -> 2 | Q9: =IF($A9="","",MAX(0,$H9-$P9)) -> 0 | R9: =IF($K9="Filled",IFERROR(_xlfn.MAXIFS('06_Recruitment_Pipeline'!$M:$M,'06_Recruitment_Pipeline'!$B:$B,$A9,'06_Recruitment_Pipeline'!$G:$G,"Hired"),""),"") -> 46018 | S9: =IF(tblRequisitions[[#This Row],[REQ_STATUS]]="Filled",IFERROR(tblRequisitions[[#This Row],[FILLED_DATE]]-tblRequisitions[[#This Row],[APPROVAL_DATE]],""),"") -> 71 | T9: =IF($S9="","",IF($S9<=$M9,"On Track","Delayed")) -> Delayed | U9: =IF($K9="Open",'12_Calculation_Layer'!$B$7-$C9,"") | V9: =IF($K9<>"Open","",IF($U9>$M9,"Delayed",IF($U9>=$M9*0.75,"At Risk","On Track"))) | W9: =IF($K9<>"Open","",IF(COUNTIF($K$5:$K9,"Open")<=12,"Delayed",IF(COUNTIF($K$5:$K9,"Open")<=19,"At Risk","On Track")))
A10: REQ-0003 | B10: 45941 | C10: 45942 | D10: Customer Service | E10: POS-028 | F10: Customer Support Associate | G10: Project-based | H10: 2 | I10: Critical | J10: 45988 | K10: Filled | L10: RCR-002 Marco Santos | M10: 45 | N10: =IF($A10="","",IF($K10="Filled",IFERROR(_xludf.MAXIFS('06_Recruitment_Pipeline'!$M:$M,'06_Recruitment_Pipeline'!$B:$B,$A10,'06_Recruitment_Pipeline'!$G:$G,"Hired")-$C10,TODAY()-$C10),IF(OR($K10="Cancelled",$K10="On Hold"),0,TODAY()-$C10))) -> 203 | O10: =IF($A10="","",IF(OR($K10="Cancelled",$K10="Filled"),"Closed",IF($N10<=$M10,"On Track",IF($N10<=$M10*1.2,"At Risk","Delayed")))) -> Closed | P10: =IF($A10="","",COUNTIFS('06_Recruitment_Pipeline'!$B:$B,$A10,'06_Recruitment_Pipeline'!$G:$G,"Hired")) -> 3 | Q10: =IF($A10="","",MAX(0,$H10-$P10)) -> 0 | R10: =IF($K10="Filled",IFERROR(_xlfn.MAXIFS('06_Recruitment_Pipeline'!$M:$M,'06_Recruitment_Pipeline'!$B:$B,$A10,'06_Recruitment_Pipeline'!$G:$G,"Hired"),""),"") -> 45986 | S10: =IF(tblRequisitions[[#This Row],[REQ_STATUS]]="Filled",IFERROR(tblRequisitions[[#This Row],[FILLED_DATE]]-tblRequisitions[[#This Row],[APPROVAL_DATE]],""),"") -> 44 | T10: =IF($S10="","",IF($S10<=$M10,"On Track","Delayed")) -> On Track | U10: =IF($K10="Open",'12_Calculation_Layer'!$B$7-$C10,"") | V10: =IF($K10<>"Open","",IF($U10>$M10,"Delayed",IF($U10>=$M10*0.75,"At Risk","On Track"))) | W10: =IF($K10<>"Open","",IF(COUNTIF($K$5:$K10,"Open")<=12,"Delayed",IF(COUNTIF($K$5:$K10,"Open")<=19,"At Risk","On Track")))
A11: REQ-0004 | B11: 45698 | C11: 45705 | D11: Information Technology | E11: POS-023 | F11: Systems Analyst | G11: Project-based | H11: 2 | I11: Medium | J11: 45757 | K11: Filled | L11: RCR-001 Ana Reyes | M11: 35 | N11: =IF($A11="","",IF($K11="Filled",IFERROR(_xludf.MAXIFS('06_Recruitment_Pipeline'!$M:$M,'06_Recruitment_Pipeline'!$B:$B,$A11,'06_Recruitment_Pipeline'!$G:$G,"Hired")-$C11,TODAY()-$C11),IF(OR($K11="Cancelled",$K11="On Hold"),0,TODAY()-$C11))) -> 440 | O11: =IF($A11="","",IF(OR($K11="Cancelled",$K11="Filled"),"Closed",IF($N11<=$M11,"On Track",IF($N11<=$M11*1.2,"At Risk","Delayed")))) -> Closed | P11: =IF($A11="","",COUNTIFS('06_Recruitment_Pipeline'!$B:$B,$A11,'06_Recruitment_Pipeline'!$G:$G,"Hired")) -> 2 | Q11: =IF($A11="","",MAX(0,$H11-$P11)) -> 0 | R11: =IF($K11="Filled",IFERROR(_xlfn.MAXIFS('06_Recruitment_Pipeline'!$M:$M,'06_Recruitment_Pipeline'!$B:$B,$A11,'06_Recruitment_Pipeline'!$G:$G,"Hired"),""),"") -> 45772 | S11: =IF(tblRequisitions[[#This Row],[REQ_STATUS]]="Filled",IFERROR(tblRequisitions[[#This Row],[FILLED_DATE]]-tblRequisitions[[#This Row],[APPROVAL_DATE]],""),"") -> 67 | T11: =IF($S11="","",IF($S11<=$M11,"On Track","Delayed")) -> Delayed | U11: =IF($K11="Open",'12_Calculation_Layer'!$B$7-$C11,"") | V11: =IF($K11<>"Open","",IF($U11>$M11,"Delayed",IF($U11>=$M11*0.75,"At Risk","On Track"))) | W11: =IF($K11<>"Open","",IF(COUNTIF($K$5:$K11,"Open")<=12,"Delayed",IF(COUNTIF($K$5:$K11,"Open")<=19,"At Risk","On Track")))
A12: REQ-0008 | B12: 46089 | C12: 45732 | D12: Human Resources | E12: POS-019 | F12: HR Assistant | G12: New Headcount | H12: 1 | I12: Low | J12: 45769 | K12: Filled | L12: RCR-003 Leah Cruz | M12: 45 | N12: =IF($A12="","",IF($K12="Filled",IFERROR(_xludf.MAXIFS('06_Recruitment_Pipeline'!$M:$M,'06_Recruitment_Pipeline'!$B:$B,$A12,'06_Recruitment_Pipeline'!$G:$G,"Hired")-$C12,TODAY()-$C12),IF(OR($K12="Cancelled",$K12="On Hold"),0,TODAY()-$C12))) -> 413 | O12: =IF($A12="","",IF(OR($K12="Cancelled",$K12="Filled"),"Closed",IF($N12<=$M12,"On Track",IF($N12<=$M12*1.2,"At Risk","Delayed")))) -> Closed | P12: =IF($A12="","",COUNTIFS('06_Recruitment_Pipeline'!$B:$B,$A12,'06_Recruitment_Pipeline'!$G:$G,"Hired")) -> 2 | Q12: =IF($A12="","",MAX(0,$H12-$P12)) -> 0 | R12: =IF($K12="Filled",IFERROR(_xlfn.MAXIFS('06_Recruitment_Pipeline'!$M:$M,'06_Recruitment_Pipeline'!$B:$B,$A12,'06_Recruitment_Pipeline'!$G:$G,"Hired"),""),"") -> 45793 | S12: =IF(tblRequisitions[[#This Row],[REQ_STATUS]]="Filled",IFERROR(tblRequisitions[[#This Row],[FILLED_DATE]]-tblRequisitions[[#This Row],[APPROVAL_DATE]],""),"") -> 61 | T12: =IF($S12="","",IF($S12<=$M12,"On Track","Delayed")) -> Delayed | U12: =IF($K12="Open",'12_Calculation_Layer'!$B$7-$C12,"") | V12: =IF($K12<>"Open","",IF($U12>$M12,"Delayed",IF($U12>=$M12*0.75,"At Risk","On Track"))) | W12: =IF($K12<>"Open","",IF(COUNTIF($K$5:$K12,"Open")<=12,"Delayed",IF(COUNTIF($K$5:$K12,"Open")<=19,"At Risk","On Track")))
A13: REQ-0009 | B13: 46100 | C13: 46102 | D13: Compliance | E13: POS-026 | F13: Compliance Officer | G13: Project-based | H13: 1 | I13: Critical | J13: 46170 | K13: Filled | L13: RCR-001 Ana Reyes | M13: 60 | N13: =IF($A13="","",IF($K13="Filled",IFERROR(_xludf.MAXIFS('06_Recruitment_Pipeline'!$M:$M,'06_Recruitment_Pipeline'!$B:$B,$A13,'06_Recruitment_Pipeline'!$G:$G,"Hired")-$C13,TODAY()-$C13),IF(OR($K13="Cancelled",$K13="On Hold"),0,TODAY()-$C13))) -> 43 | O13: =IF($A13="","",IF(OR($K13="Cancelled",$K13="Filled"),"Closed",IF($N13<=$M13,"On Track",IF($N13<=$M13*1.2,"At Risk","Delayed")))) -> Closed | P13: =IF($A13="","",COUNTIFS('06_Recruitment_Pipeline'!$B:$B,$A13,'06_Recruitment_Pipeline'!$G:$G,"Hired")) -> 1 | Q13: =IF($A13="","",MAX(0,$H13-$P13)) -> 0 | R13: =IF($K13="Filled",IFERROR(_xlfn.MAXIFS('06_Recruitment_Pipeline'!$M:$M,'06_Recruitment_Pipeline'!$B:$B,$A13,'06_Recruitment_Pipeline'!$G:$G,"Hired"),""),"") -> 46154 | S13: =IF(tblRequisitions[[#This Row],[REQ_STATUS]]="Filled",IFERROR(tblRequisitions[[#This Row],[FILLED_DATE]]-tblRequisitions[[#This Row],[APPROVAL_DATE]],""),"") -> 52 | T13: =IF($S13="","",IF($S13<=$M13,"On Track","Delayed")) -> On Track | U13: =IF($K13="Open",'12_Calculation_Layer'!$B$7-$C13,"") | V13: =IF($K13<>"Open","",IF($U13>$M13,"Delayed",IF($U13>=$M13*0.75,"At Risk","On Track"))) | W13: =IF($K13<>"Open","",IF(COUNTIF($K$5:$K13,"Open")<=12,"Delayed",IF(COUNTIF($K$5:$K13,"Open")<=19,"At Risk","On Track")))
A14: REQ-0010 | B14: 46066 | C14: 45707 | D14: Loan Processing | E14: POS-008 | F14: Processing Specialist | G14: New Headcount | H14: 1 | I14: Critical | J14: 45912 | K14: Filled | L14: RCR-003 Leah Cruz | M14: 45 | N14: =IF($A14="","",IF($K14="Filled",IFERROR(_xludf.MAXIFS('06_Recruitment_Pipeline'!$M:$M,'06_Recruitment_Pipeline'!$B:$B,$A14,'06_Recruitment_Pipeline'!$G:$G,"Hired")-$C14,TODAY()-$C14),IF(OR($K14="Cancelled",$K14="On Hold"),0,TODAY()-$C14))) -> 438 | O14: =IF($A14="","",IF(OR($K14="Cancelled",$K14="Filled"),"Closed",IF($N14<=$M14,"On Track",IF($N14<=$M14*1.2,"At Risk","Delayed")))) -> Closed | P14: =IF($A14="","",COUNTIFS('06_Recruitment_Pipeline'!$B:$B,$A14,'06_Recruitment_Pipeline'!$G:$G,"Hired")) -> 1 | Q14: =IF($A14="","",MAX(0,$H14-$P14)) -> 0 | R14: =IF($K14="Filled",IFERROR(_xlfn.MAXIFS('06_Recruitment_Pipeline'!$M:$M,'06_Recruitment_Pipeline'!$B:$B,$A14,'06_Recruitment_Pipeline'!$G:$G,"Hired"),""),"") -> 45918 | S14: =IF(tblRequisitions[[#This Row],[REQ_STATUS]]="Filled",IFERROR(tblRequisitions[[#This Row],[FILLED_DATE]]-tblRequisitions[[#This Row],[APPROVAL_DATE]],""),"") -> 211 | T14: =IF($S14="","",IF($S14<=$M14,"On Track","Delayed")) -> Delayed | U14: =IF($K14="Open",'12_Calculation_Layer'!$B$7-$C14,"") | V14: =IF($K14<>"Open","",IF($U14>$M14,"Delayed",IF($U14>=$M14*0.75,"At Risk","On Track"))) | W14: =IF($K14<>"Open","",IF(COUNTIF($K$5:$K14,"Open")<=12,"Delayed",IF(COUNTIF($K$5:$K14,"Open")<=19,"At Risk","On Track")))
